<?xml version="1.0" encoding="UTF-8"?>
<!-- Generated by org.testng.reporters.JUnitReportReporter -->
<testsuite hostname="INVIND760" failures="2" tests="16" name="testCases.TC_0020_Fund_Transfer_Invalid_Value_Test" time="237.187" errors="0" timestamp="13 Apr 2023 08:14:23 GMT" skipped="0">
  <testcase classname="testCases.TC_0020_Fund_Transfer_Invalid_Value_Test" name="TC_0020_Fund_Transfer_Invalid_Value" time="14.721"/>
  <testcase classname="testCases.TC_0020_Fund_Transfer_Invalid_Value_Test" name="TC_0020_Fund_Transfer_Invalid_Value" time="13.462">
    <failure message="expected [true] but found [false]" type="java.lang.AssertionError">
      <![CDATA[java.lang.AssertionError: expected [true] but found [false]
at org.testng.Assert.fail(Assert.java:96)
at org.testng.Assert.failNotEquals(Assert.java:776)
at org.testng.Assert.assertTrue(Assert.java:44)
at org.testng.Assert.assertTrue(Assert.java:54)
at testCases.TC_0020_Fund_Transfer_Invalid_Value_Test.TC_0020_Fund_Transfer_Invalid_Value(TC_0020_Fund_Transfer_Invalid_Value_Test.java:178)
at java.base/jdk.internal.reflect.NativeMethodAccessorImpl.invoke0(Native Method)
at java.base/jdk.internal.reflect.NativeMethodAccessorImpl.invoke(NativeMethodAccessorImpl.java:77)
at java.base/jdk.internal.reflect.DelegatingMethodAccessorImpl.invoke(DelegatingMethodAccessorImpl.java:43)
at java.base/java.lang.reflect.Method.invoke(Method.java:568)
at org.testng.internal.MethodInvocationHelper.invokeMethod(MethodInvocationHelper.java:124)
at org.testng.internal.Invoker.invokeMethod(Invoker.java:583)
at org.testng.internal.Invoker.invokeTestMethod(Invoker.java:719)
at org.testng.internal.Invoker.invokeTestMethods(Invoker.java:989)
at org.testng.internal.TestMethodWorker.invokeTestMethods(TestMethodWorker.java:125)
at org.testng.internal.TestMethodWorker.run(TestMethodWorker.java:109)
at org.testng.TestRunner.privateRun(TestRunner.java:648)
at org.testng.TestRunner.run(TestRunner.java:505)
at org.testng.SuiteRunner.runTest(SuiteRunner.java:455)
at org.testng.SuiteRunner.runSequentially(SuiteRunner.java:450)
at org.testng.SuiteRunner.privateRun(SuiteRunner.java:415)
at org.testng.SuiteRunner.run(SuiteRunner.java:364)
at org.testng.SuiteRunnerWorker.runSuite(SuiteRunnerWorker.java:52)
at org.testng.SuiteRunnerWorker.run(SuiteRunnerWorker.java:84)
at org.testng.TestNG.runSuitesSequentially(TestNG.java:1208)
at org.testng.TestNG.runSuitesLocally(TestNG.java:1137)
at org.testng.TestNG.runSuites(TestNG.java:1049)
at org.testng.TestNG.run(TestNG.java:1017)
at org.testng.remote.AbstractRemoteTestNG.run(AbstractRemoteTestNG.java:115)
at org.testng.remote.RemoteTestNG.initAndRun(RemoteTestNG.java:251)
at org.testng.remote.RemoteTestNG.main(RemoteTestNG.java:77)
]]>
    </failure>
  </testcase> <!-- TC_0020_Fund_Transfer_Invalid_Value -->
  <testcase classname="testCases.TC_0020_Fund_Transfer_Invalid_Value_Test" name="TC_0020_Fund_Transfer_Invalid_Value" time="14.583"/>
  <testcase classname="testCases.TC_0020_Fund_Transfer_Invalid_Value_Test" name="TC_0020_Fund_Transfer_Invalid_Value" time="14.186"/>
  <testcase classname="testCases.TC_0020_Fund_Transfer_Invalid_Value_Test" name="TC_0020_Fund_Transfer_Invalid_Value" time="14.595"/>
  <testcase classname="testCases.TC_0020_Fund_Transfer_Invalid_Value_Test" name="TC_0020_Fund_Transfer_Invalid_Value" time="15.531"/>
  <testcase classname="testCases.TC_0020_Fund_Transfer_Invalid_Value_Test" name="TC_0020_Fund_Transfer_Invalid_Value" time="14.667"/>
  <testcase classname="testCases.TC_0020_Fund_Transfer_Invalid_Value_Test" name="TC_0020_Fund_Transfer_Invalid_Value" time="14.348"/>
  <testcase classname="testCases.TC_0020_Fund_Transfer_Invalid_Value_Test" name="TC_0020_Fund_Transfer_Invalid_Value" time="16.029"/>
  <testcase classname="testCases.TC_0020_Fund_Transfer_Invalid_Value_Test" name="TC_0020_Fund_Transfer_Invalid_Value" time="14.425"/>
  <testcase classname="testCases.TC_0020_Fund_Transfer_Invalid_Value_Test" name="TC_0020_Fund_Transfer_Invalid_Value" time="15.060"/>
  <testcase classname="testCases.TC_0020_Fund_Transfer_Invalid_Value_Test" name="TC_0020_Fund_Transfer_Invalid_Value" time="14.520">
    <failure message="expected [true] but found [false]" type="java.lang.AssertionError">
      <![CDATA[java.lang.AssertionError: expected [true] but found [false]
at org.testng.Assert.fail(Assert.java:96)
at org.testng.Assert.failNotEquals(Assert.java:776)
at org.testng.Assert.assertTrue(Assert.java:44)
at org.testng.Assert.assertTrue(Assert.java:54)
at testCases.TC_0020_Fund_Transfer_Invalid_Value_Test.TC_0020_Fund_Transfer_Invalid_Value(TC_0020_Fund_Transfer_Invalid_Value_Test.java:178)
at java.base/jdk.internal.reflect.NativeMethodAccessorImpl.invoke0(Native Method)
at java.base/jdk.internal.reflect.NativeMethodAccessorImpl.invoke(NativeMethodAccessorImpl.java:77)
at java.base/jdk.internal.reflect.DelegatingMethodAccessorImpl.invoke(DelegatingMethodAccessorImpl.java:43)
at java.base/java.lang.reflect.Method.invoke(Method.java:568)
at org.testng.internal.MethodInvocationHelper.invokeMethod(MethodInvocationHelper.java:124)
at org.testng.internal.Invoker.invokeMethod(Invoker.java:583)
at org.testng.internal.Invoker.invokeTestMethod(Invoker.java:719)
at org.testng.internal.Invoker.invokeTestMethods(Invoker.java:989)
at org.testng.internal.TestMethodWorker.invokeTestMethods(TestMethodWorker.java:125)
at org.testng.internal.TestMethodWorker.run(TestMethodWorker.java:109)
at org.testng.TestRunner.privateRun(TestRunner.java:648)
at org.testng.TestRunner.run(TestRunner.java:505)
at org.testng.SuiteRunner.runTest(SuiteRunner.java:455)
at org.testng.SuiteRunner.runSequentially(SuiteRunner.java:450)
at org.testng.SuiteRunner.privateRun(SuiteRunner.java:415)
at org.testng.SuiteRunner.run(SuiteRunner.java:364)
at org.testng.SuiteRunnerWorker.runSuite(SuiteRunnerWorker.java:52)
at org.testng.SuiteRunnerWorker.run(SuiteRunnerWorker.java:84)
at org.testng.TestNG.runSuitesSequentially(TestNG.java:1208)
at org.testng.TestNG.runSuitesLocally(TestNG.java:1137)
at org.testng.TestNG.runSuites(TestNG.java:1049)
at org.testng.TestNG.run(TestNG.java:1017)
at org.testng.remote.AbstractRemoteTestNG.run(AbstractRemoteTestNG.java:115)
at org.testng.remote.RemoteTestNG.initAndRun(RemoteTestNG.java:251)
at org.testng.remote.RemoteTestNG.main(RemoteTestNG.java:77)
]]>
    </failure>
  </testcase> <!-- TC_0020_Fund_Transfer_Invalid_Value -->
  <testcase classname="testCases.TC_0020_Fund_Transfer_Invalid_Value_Test" name="TC_0020_Fund_Transfer_Invalid_Value" time="15.720"/>
  <testcase classname="testCases.TC_0020_Fund_Transfer_Invalid_Value_Test" name="TC_0020_Fund_Transfer_Invalid_Value" time="15.721"/>
  <testcase classname="testCases.TC_0020_Fund_Transfer_Invalid_Value_Test" name="TC_0020_Fund_Transfer_Invalid_Value" time="14.558"/>
  <testcase classname="testCases.TC_0020_Fund_Transfer_Invalid_Value_Test" name="TC_0020_Fund_Transfer_Invalid_Value" time="15.061"/>
</testsuite> <!-- testCases.TC_0020_Fund_Transfer_Invalid_Value_Test -->
